<mujoco model="ant">
  <compiler angle="degree" coordinate="local" inertiafromgeom="true"/>
  <option integrator="RK4" timestep="0.01"/>
  <!-- <custom>
    <numeric data="0.0 0.0 0.55 1.0 0.0 0.0 0.0 0.0 1.0 0.0 -1.0 0.0 -1.0 0.0 1.0" name="init_qpos"/>
  </custom> -->
  <default>
    <joint armature="1" damping="1" limited="true"/>
    <geom conaffinity="1" condim="3" density="5.0" friction="0.5 0.5 0.5" margin="0.01" rgba="0.8 0.6 0.4 1"/>
  </default>
  <asset>
    <texture builtin="gradient" height="100" rgb1="1 1 1" rgb2="0 0 0" type="skybox" width="100"/>
    <texture builtin="flat" height="1278" mark="cross" markrgb="1 1 1" name="texgeom" random="0.01" rgb1="0.8 0.6 0.4" rgb2="0.8 0.6 0.4" type="cube" width="127"/>
    <texture builtin="checker" height="100" name="texplane" rgb1=".1 .2 .3" rgb2=".2 .3 .4" type="2d" width="100"/>
    <texture builtin="checker" height="100" name="texplane2" rgb1="1 1 1" rgb2=".2 .3 .4" type="2d" width="100"/>
    <material name="MatPlane" reflectance="0.5" shininess="1" specular="1" texrepeat="10 40" texture="texplane"/>
    <material name="MatPlane_2" reflectance="0.5" shininess="1" specular="1" texrepeat="5 5" texture="texplane2"/>
    <material name="geom" texture="texgeom" texuniform="true"/>
  </asset>
  <worldbody>
    <!-- test object -->

    <body name="agent_torso" pos="0 0 0.75">
      <camera name="track" mode="trackcom" pos="0 -3 0.3" xyaxes="1 0 0 0 0 1"/>
      <geom name="agent_torso_geom" pos="0 0 0" size="0.25" type="sphere"/>
      <joint armature="0" damping="0" limited="false" margin="0.01" name="root" pos="0 0 0" type="free"/>
      <body name="agent_front_left_leg" pos="0 0 0">
        <geom fromto="0.0 0.0 0.0 0.2 0.2 0.0" name="aux_1_geom" size="0.08" type="capsule"/>
        <body name="aux_1" pos="0.2 0.2 0">
          <joint axis="0 0 1" name="hip_1" pos="0.0 0.0 0.0" range="-30 30" type="hinge"/>
          <geom fromto="0.0 0.0 0.0 0.2 0.2 0.0" name="agent_left_leg_geom" size="0.08" type="capsule"/>
          <body pos="0.2 0.2 0">
            <joint axis="-1 1 0" name="ankle_1" pos="0.0 0.0 0.0" range="30 70" type="hinge"/>
            <geom fromto="0.0 0.0 0.0 0.4 0.4 0.0" name="agent_left_ankle_geom" size="0.08" type="capsule"/>
          </body>
        </body>
      </body>
      <body name="agent_front_right_leg" pos="0 0 0">
        <geom fromto="0.0 0.0 0.0 -0.2 0.2 0.0" name="aux_2_geom" size="0.08" type="capsule"/>
        <body name="aux_2" pos="-0.2 0.2 0">
          <joint axis="0 0 1" name="hip_2" pos="0.0 0.0 0.0" range="-30 30" type="hinge"/>
          <geom fromto="0.0 0.0 0.0 -0.2 0.2 0.0" name="agent_right_leg_geom" size="0.08" type="capsule"/>
          <body pos="-0.2 0.2 0">
            <joint axis="1 1 0" name="ankle_2" pos="0.0 0.0 0.0" range="-70 -30" type="hinge"/>
            <geom fromto="0.0 0.0 0.0 -0.4 0.4 0.0" name="agent_right_ankle_geom" size="0.08" type="capsule"/>
          </body>
        </body>
      </body>
      <body name="agent_back_leg" pos="0 0 0">
        <geom fromto="0.0 0.0 0.0 -0.2 -0.2 0.0" name="aux_3_geom" size="0.08" type="capsule"/>
        <body name="aux_3" pos="-0.2 -0.2 0">
          <joint axis="0 0 1" name="hip_3" pos="0.0 0.0 0.0" range="-30 30" type="hinge"/>
          <geom fromto="0.0 0.0 0.0 -0.2 -0.2 0.0" name="agent_back_leg_geom" size="0.08" type="capsule"/>
          <body pos="-0.2 -0.2 0">
            <joint axis="-1 1 0" name="ankle_3" pos="0.0 0.0 0.0" range="-70 -30" type="hinge"/>
            <geom fromto="0.0 0.0 0.0 -0.4 -0.4 0.0" name="agent_third_ankle_geom" size="0.08" type="capsule"/>
          </body>
        </body>
      </body>
      <body name="agent_right_back_leg" pos="0 0 0">
        <geom fromto="0.0 0.0 0.0 0.2 -0.2 0.0" name="aux_4_geom" size="0.08" type="capsule"/>
        <body name="aux_4" pos="0.2 -0.2 0">
          <joint axis="0 0 1" name="hip_4" pos="0.0 0.0 0.0" range="-30 30" type="hinge"/>
          <geom fromto="0.0 0.0 0.0 0.2 -0.2 0.0" name="agent_rightback_leg_geom" size="0.08" type="capsule"/>
          <body pos="0.2 -0.2 0">
            <joint axis="1 1 0" name="ankle_4" pos="0.0 0.0 0.0" range="30 70" type="hinge"/>
            <geom fromto="0.0 0.0 0.0 0.4 -0.4 0.0" name="agent_fourth_ankle_geom" size="0.08" type="capsule"/>
          </body>
        </body>
      </body>
    </body>
    <geom name="curbleft0" pos="-5.75 10 0.5" conaffinity="1" rgba="0.9 0.3 0.3 1" size="4.25 1 1" type="box"/>
    <geom name="curbright0" pos="5.75 10 0.5" conaffinity="1" rgba="0.9 0.3 0.3 1" size="4.25 1 1" type="box"/>
    <geom name="curbleft1" pos="-5.75 77 0.5" conaffinity="1" rgba="0.9 0.3 0.3 1" size="4.25 1 1" type="box"/>
    <geom name="curbright1" pos="5.75 77 0.5" conaffinity="1" rgba="0.9 0.3 0.3 1" size="4.25 1 1" type="box"/>
    <geom name="curbleft2" pos="-5.75 144 0.5" conaffinity="1" rgba="0.9 0.3 0.3 1" size="4.25 1 1" type="box"/>
    <geom name="curbright2" pos="5.75 144 0.5" conaffinity="1" rgba="0.9 0.3 0.3 1" size="4.25 1 1" type="box"/>
    <geom name="curbleft3" pos="-5.75 211 0.5" conaffinity="1" rgba="0.9 0.3 0.3 1" size="4.25 1 1" type="box"/>
    <geom name="curbright3" pos="5.75 211 0.5" conaffinity="1" rgba="0.9 0.3 0.3 1" size="4.25 1 1" type="box"/>




    <light cutoff="100" diffuse="1 1 1" dir="-0 0 -1.3" directional="true" exponent="1" pos="0 0 1.3" specular=".1 .1 .1"/>
    <geom name="midplane0" pos="0 10 -0.5" conaffinity="1" rgba="0.3 0.3 0.9 1" friction="1 1 1" size="10 20 0.5" type="box" priority = "3"/>
    <geom name="midplane1" pos="0 71.5 -0.5" conaffinity="1" rgba="0.3 0.3 0.9 1" friction="1 1 1" size="10 25.5 0.5" type="box" priority = "3"/>
    <geom name="midplane2" pos="0 138.5 -0.5" conaffinity="1" rgba="0.3 0.3 0.9 1" friction="1 1 1" size="10 25.5 0.5" type="box" priority = "3"/>
    <geom name="midplane3" pos="0 210.5 -0.5" conaffinity="1" rgba="0.3 0.3 0.9 1" friction="1 1 1" size="10 30.5 0.5" type="box" priority = "3"/>

    <geom name="bridge1" pos="0 38 -0.5" conaffinity="1" rgba="0.9 0.3 0.3 1" size="1.5 8 0.5" type="box" />
    <geom name="bridge2" pos="0 105 -0.5" conaffinity="1" rgba="0.9 0.3 0.3 1" size="1.5 8 0.5" type="box" />
    <geom name="bridge3" pos="0 172 -0.5" conaffinity="1" rgba="0.9 0.3 0.3 1" size="1.5 8 0.5" type="box" />

    <geom name="coin_geom1_0" pos= "0 56 0.3" conaffinity="0" contype="0" type="sphere" size=".3" condim="3"  rgba="0.2 0.9 0.2 1" />
    <geom name="coin_geom2_0" conaffinity="0" contype="0" type="sphere" size=".3" condim="3"  pos="0 62 0.3" rgba="0.2 0.9 0.2 1" />
    <geom name="coin_geom1_1" pos= "0 123 0.3" conaffinity="0" contype="0" type="sphere" size=".3" condim="3"  rgba="0.2 0.9 0.2 1" />
    <geom name="coin_geom2_1" conaffinity="0" contype="0" type="sphere" size=".3" condim="3"  pos="0 129 0.3" rgba="0.2 0.9 0.2 1" />
    <geom name="coin_geom1_2" pos= "0 190 0.3" conaffinity="0" contype="0" type="sphere" size=".3" condim="3"  rgba="0.2 0.9 0.2 1" />
    <geom name="coin_geom2_2" conaffinity="0" contype="0" type="sphere" size=".3" condim="3"  pos="0 196 0.3" rgba="0.2 0.9 0.2 1" />
  </worldbody>
  <actuator>
    <motor ctrllimited="true" ctrlrange="-1.0 1.0" joint="hip_4" gear="150"/>
    <motor ctrllimited="true" ctrlrange="-1.0 1.0" joint="ankle_4" gear="150"/>
    <motor ctrllimited="true" ctrlrange="-1.0 1.0" joint="hip_1" gear="150"/>
    <motor ctrllimited="true" ctrlrange="-1.0 1.0" joint="ankle_1" gear="150"/>
    <motor ctrllimited="true" ctrlrange="-1.0 1.0" joint="hip_2" gear="150"/>
    <motor ctrllimited="true" ctrlrange="-1.0 1.0" joint="ankle_2" gear="150"/>
    <motor ctrllimited="true" ctrlrange="-1.0 1.0" joint="hip_3" gear="150"/>
    <motor ctrllimited="true" ctrlrange="-1.0 1.0" joint="ankle_3" gear="150"/>
  </actuator>
</mujoco>
