<mujoco model="ant">
  <compiler angle="degree" coordinate="local" inertiafromgeom="true"/>
  <option integrator="RK4" timestep="0.01"/>
  <custom>
    <numeric data="0.0 0.0 0.55 1.0 0.0 0.0 0.0 0.0 1.0 0.0 -1.0 0.0 -1.0 0.0 1.0" name="init_qpos"/>
  </custom>
  <default>
    <joint armature="1" damping="1" limited="true"/>
    <geom conaffinity="1" condim="3" density="5.0" friction="0.5 0.5 0.5" margin="0.01" rgba="0.8 0.6 0.4 1"/>
  </default>
  <asset>
    <texture builtin="gradient" height="100" rgb1="1 1 1" rgb2="0 0 0" type="skybox" width="100"/>
    <texture builtin="flat" height="1278" mark="cross" markrgb="1 1 1" name="texgeom" random="0.01" rgb1="0.8 0.6 0.4" rgb2="0.8 0.6 0.4" type="cube" width="127"/>
    <texture builtin="checker" height="100" name="texplane" rgb1=".1 .2 .3" rgb2=".2 .3 .4" type="2d" width="100"/>
    <texture builtin="checker" height="100" name="texplane2" rgb1="1 1 1" rgb2=".2 .3 .4" type="2d" width="100"/>
    <material name="MatPlane" reflectance="0.5" shininess="1" specular="1" texrepeat="10 40" texture="texplane"/>
    <material name="MatPlane_2" reflectance="0.5" shininess="1" specular="1" texrepeat="5 5" texture="texplane2"/>
    <material name="geom" texture="texgeom" texuniform="true"/>
  </asset>
  <worldbody>
    <!-- test object -->
    
    <body name="agent_ball_body" pos = "0 0 0.5">
        <!-- <inertial pos="0 0 0" mass="0.179594" diaginertia="8.80012e-05 8.80012e-05 8.80012e-05" /> -->
        <!-- <inertial pos="0 0 0" mass="10" diaginertia="8.80012e-05 8.80012e-05 8.80012e-05" /> -->
        <geom name="agent_ball_geom" type="sphere" size=".5" condim="4" rgba="1 0 0 1" pos="0 0 0" />
        <joint name="OBJTx" pos="0 0 0" axis="1 0 0" type="slide" limited="false" damping="0" />
        <joint name="OBJTy" pos="0 0 0" axis="0 1 0" type="slide" limited="false" damping="0" />
        <joint name="OBJTz" pos="0 0 0" axis="0 0 1" type="slide" limited="false" damping="0" />
        <!-- <joint name="OBJRx" pos="0 0 0" axis="1 0 0" limited="false" damping="0" />
        <joint name="OBJRy" pos="0 0 0" axis="0 1 0" limited="false" damping="0" />
        <joint name="OBJRz" pos="0 0 0" axis="0 0 1" limited="false" damping="0" /> -->
    </body>
    <geom conaffinity="1" condim="3" material="MatPlane_2" name="goal" pos="0 25 -0.09" rgba="0.6 0.6 0.6 1" size="3 0.1 0" type="cylinder"/>
    <geom name="curbleft" pos="-5 10 0.5" conaffinity="1" rgba="0.9 0.3 0.3 1" size="1 1 1" type="box"/>
    <geom name="curbright" pos="5 10 0.5" conaffinity="1" rgba="0.9 0.3 0.3 1" size="1 1 1" type="box"/>
    <geom name="curend" pos="0 40 0.5" conaffinity="1" rgba="0.9 0.3 0.3 1" size="10 1 1" type="box"/>


    <light cutoff="100" diffuse="1 1 1" dir="-0 0 -1.3" directional="true" exponent="1" pos="0 0 1.3" specular=".1 .1 .1"/>
    <geom conaffinity="1" condim="3" material="MatPlane" name="floor" pos="0 0 0" rgba="0.8 0.9 0.8 1" size="10 40 40" type="plane"/>

  </worldbody>
  <actuator>
    <velocity ctrllimited="true" ctrlrange="-2.0 2.0" joint="OBJTx" kv=50/>
    <velocity ctrllimited="true" ctrlrange="-2.0 2.0" joint="OBJTy" kv=50/>
    <!-- <motor ctrllimited="true" ctrlrange="-10.0 10.0" joint="OBJTx" />
    <motor ctrllimited="true" ctrlrange="-10.0 10.0" joint="OBJTy" /> -->

  </actuator>
</mujoco>